<?xml version='1.0'?>

<robot name="rocky_bot" xmlns:xacro="http://www.ros.org/wiki/xacro">

  <xacro:include filename="$(find rocky_bot)/urdf/rocky_bot.gazebo" />

  <!-- Colors in rviz -->
  <material name="red">
    <color rgba="1 0 0 1"/>
  </material>
  <material name="black">
    <color rgba="0 0 0 1"/>
  </material>
  <material name="orange">
    <color rgba="0 0 1 1"/>
  </material>


  <!-- Colors in gazebo -->
  <gazebo reference="left_front_wheel">
    <material>Gazebo/Black</material>
  </gazebo>

  <gazebo reference="left_rear_wheel">
    <material>Gazebo/Black</material>
  </gazebo>

  <gazebo reference="right_front_wheel">
    <material>Gazebo/Black</material>
  </gazebo>

  <gazebo reference="right_rear_wheel">
    <material>Gazebo/Black</material>
  </gazebo>

  <gazebo reference="chassis">
    <material>Gazebo/Orange</material>
  </gazebo>

  <gazebo reference="camera">
    <material>Gazebo/Red</material>
  </gazebo>
  <!-- Colors End -->

  <link name="robot_footprint"></link>

  <joint name="robot_footprint_joint" type="fixed">
    <origin xyz="0 0 0" rpy="0 0 0" />
    <parent link="robot_footprint"/>
    <child link="chassis" />
  </joint>

  <link name='chassis'>
    <pose>0 0 0.1 0 0 0</pose>

    <inertial>
      <mass value="15.0"/>
      <origin xyz="0.0 0 0" rpy=" 0 0 0"/>
      <inertia
          ixx="0.1" ixy="0" ixz="0"
          iyy="0.1" iyz="0"
          izz="0.1"
      />
    </inertial>

    <collision name='collision'>
      <origin xyz="0 0 0" rpy=" 0 0 0"/> 
      <geometry>
        <box size=".6 .3 .1"/>
      </geometry>
    </collision>

    <visual name='chassis_visual'>
      <origin xyz="0 0 0" rpy=" 0 0 0"/>
      <geometry>
        <box size=".6 .3 .1"/>
      </geometry>
      <material name="orange"/>
    </visual>
  </link>

  <!-- left front wheel -->
  <link name="left_front_wheel">
    <inertial>
      <origin xyz="0.0 0.0 0.0" rpy="0.0 0.0 0.0"/>
      <mass value="5.0"/>
      <inertia ixx="0.1" ixy="0.0" ixz="0.0" iyy="0.1" iyz="0.0" izz="0.1"/>
    </inertial>
    <visual name="left_front_wheel_visual">
      <origin xyz="0.0 0.0 0.0" rpy="0.0 1.5707 1.5707"/>
      <geometry>
        <cylinder radius="0.1" length="0.05"/>
      </geometry>
      <material name="black"/>
    </visual>
    <collision name="left_front_wheel_collision">
      <origin xyz="0.0 0.0 0.0" rpy="0.0 1.5707 1.5707"/>
      <geometry>
        <cylinder radius="0.1" length="0.05"/>
      </geometry>
    </collision>
  </link>

  <joint name="left_front_wheel_hinge" type="continuous">
    <origin xyz="0.15 0.2 0" rpy="0 0 0"/>
    <parent link="chassis"/>
    <child link="left_front_wheel"/>
    <axis xyz="0 1 0" rpy="0 0 0"/>
    <limit effort="10000" velocity="1000"/>
    <dynamics damping="1.0" friction="1.0"/>
  </joint>

  <!-- left rear wheel -->
  <link name="left_rear_wheel">
    <inertial>
      <origin xyz="0.0 0.0 0.0" rpy="0.0 0.0 0.0"/>
      <mass value="5.0"/>
      <inertia ixx="0.1" ixy="0.0" ixz="0.0" iyy="0.1" iyz="0.0" izz="0.1"/>
    </inertial>
    <visual name="left_rear_wheel_visual">
      <origin xyz="0.0 0.0 0.0" rpy="0.0 1.5707 1.5707"/>
      <geometry>
        <cylinder radius="0.1" length="0.05"/>
      </geometry>
      <material name="black"/>
    </visual>
    <collision name="left_rear_wheel_collision">
      <origin xyz="0.0 0.0 0.0" rpy="0.0 1.5707 1.5707"/>
      <geometry>
        <cylinder radius="0.1" length="0.05"/>
      </geometry>
    </collision>
  </link>

  <joint name="left_rear_wheel_hinge" type="continuous">
    <origin xyz="-0.15 0.2 0" rpy="0 0 0"/>
    <parent link="chassis"/>
    <child link="left_rear_wheel"/>
    <axis xyz="0 1 0" rpy="0 0 0"/>
    <limit effort="10000" velocity="1000"/>
    <dynamics damping="1.0" friction="1.0"/>
  </joint>

  <!-- right front wheel -->
  <link name="right_front_wheel">
    <inertial>
      <origin xyz="0.0 0.0 0.0" rpy="0.0 0.0 0.0"/>
      <mass value="5.0"/>
      <inertia ixx="0.1" ixy="0.0" ixz="0.0" iyy="0.1" iyz="0.0" izz="0.1"/>
    </inertial>
    <visual name="right_front_wheel_visual">
      <origin xyz="0.0 0.0 0.0" rpy="0.0 1.5707 1.5707"/>
      <geometry>
        <cylinder radius="0.1" length="0.05"/>
      </geometry>
      <material name="black"/>
    </visual>
    <collision name="right_front_wheel_collision">
      <origin xyz="0.0 0.0 0.0" rpy="0.0 1.5707 1.5707"/>
      <geometry>
        <cylinder radius="0.1" length="0.05"/>
      </geometry>
    </collision>
  </link>

  <joint name="right_front_wheel_hinge" type="continuous">
    <origin xyz="0.15 -0.2 0" rpy="0 0 0"/>
    <parent link="chassis"/>
    <child link="right_front_wheel"/>
    <axis xyz="0 1 0" rpy="0 0 0"/>
    <limit effort="10000" velocity="1000"/>
    <dynamics damping="1.0" friction="1.0"/>
  </joint>

  <!-- right rear wheel -->
  <link name="right_rear_wheel">
    <inertial>
      <origin xyz="0.0 0.0 0.0" rpy="0.0 0.0 0.0"/>
      <mass value="5.0"/>
      <inertia ixx="0.1" ixy="0.0" ixz="0.0" iyy="0.1" iyz="0.0" izz="0.1"/>
    </inertial>
    <visual name="right_rear_wheel_visual">
      <origin xyz="0.0 0.0 0.0" rpy="0.0 1.5707 1.5707"/>
      <geometry>
        <cylinder radius="0.1" length="0.05"/>
      </geometry>
      <material name="black"/>
    </visual>
    <collision name="right_rear_wheel_collision">
      <origin xyz="0.0 0.0 0.0" rpy="0.0 1.5707 1.5707"/>
      <geometry>
        <cylinder radius="0.1" length="0.05"/>
      </geometry>
    </collision>
  </link>

  <joint name="right_rear_wheel_hinge" type="continuous">
    <origin xyz="-0.15 -0.2 0" rpy="0 0 0"/>
    <parent link="chassis"/>
    <child link="right_rear_wheel"/>
    <axis xyz="0 1 0" rpy="0 0 0"/>
    <limit effort="10000" velocity="1000"/>
    <dynamics damping="1.0" friction="1.0"/>
  </joint>

  <!-- Sensor: Camera -->
  <link name="camera">
    <inertial>
      <origin xyz="0 0 0" rpy="0 0 0"/>
      <mass value="0.1"/>
      <inertia ixx="1e-6" ixy="0.0" ixz="0.0" iyy="1e-6" iyz="0.0" izz="1e-6"/>
    </inertial>
    <visual name="camera_visual">
      <origin xyz="0 0 0" rpy="0 0 0"/>
      <geometry>
        <box size="0.05 0.05 0.05"/>
      </geometry>
      <material name="red"/>
    </visual>
    <collision>
      <origin xyz="0 0 0" rpy="0 0 0"/>
      <geometry>
        <box size="0.05 0.05 0.05"/>
      </geometry>
    </collision>
  </link>

  <joint name="camera_joint" type="fixed">
    <origin xyz="0.3 0 0" rpy="0 0 0"/>
    <parent link="chassis"/>
    <child link="camera"/>
  </joint>>
  
  <!-- Sensor: Laser RangeFinder -->
  <link name="hokuyo">
    <inertial>
      <origin xyz="0 0 0" rpy="0 0 0"/>
      <mass value="0.1"/>
      <inertia ixx="1e-6" ixy="0.0" ixz="0.0" iyy="1e-6" iyz="0.0" izz="1e-6"/>
    </inertial>
    <visual name="hokuyo_visual">
      <origin xyz="0 0 0" rpy="0 0 0"/>
      <geometry>
        <mesh filename="package://rocky_bot/meshes/hokuyo.dae"/>
      </geometry>
    </visual>
    <collision>
      <origin xyz="0 0 0" rpy="0 0 0"/>
      <geometry>
        <box size="0.1 0.1 0.1"/>
      </geometry>
    </collision>
  </link>

  <joint name="hokuyo_joint" type="fixed">
    <origin xyz=".25 0 .1" rpy="0 0 0"/>
    <parent link="chassis"/>
    <child link="hokuyo"/>
  </joint>

</robot>
